Exception ignored in: <bound method BaseEventLoop.__del__ of <_UnixSelectorEventLoop running=False closed=False debug=False>>
Traceback (most recent call last):
  File "/usr/lib/python3.6/asyncio/base_events.py", line 526, in __del__
NameError: name 'ResourceWarning' is not defined
Exception ignored in: <bound method BaseEventLoop.__del__ of <_UnixSelectorEventLoop running=False closed=False debug=False>>
Traceback (most recent call last):
  File "/usr/lib/python3.6/asyncio/base_events.py", line 526, in __del__
NameError: name 'ResourceWarning' is not defined
Exception ignored in: <bound method BaseEventLoop.__del__ of <_UnixSelectorEventLoop running=False closed=False debug=False>>
Traceback (most recent call last):
  File "/usr/lib/python3.6/asyncio/base_events.py", line 526, in __del__
NameError: name 'ResourceWarning' is not defined
Exception ignored in: <bound method BaseEventLoop.__del__ of <_UnixSelectorEventLoop running=False closed=False debug=False>>
Traceback (most recent call last):
  File "/usr/lib/python3.6/asyncio/base_events.py", line 526, in __del__
NameError: name 'ResourceWarning' is not defined
Exception ignored in: <bound method BaseEventLoop.__del__ of <_UnixSelectorEventLoop running=False closed=False debug=False>>
Traceback (most recent call last):
  File "/usr/lib/python3.6/asyncio/base_events.py", line 526, in __del__
NameError: name 'ResourceWarning' is not defined
Exception ignored in: <bound method BaseEventLoop.__del__ of <_UnixSelectorEventLoop running=False closed=False debug=False>>
Traceback (most recent call last):
  File "/usr/lib/python3.6/asyncio/base_events.py", line 526, in __del__
NameError: name 'ResourceWarning' is not defined
Exception ignored in: <bound method BaseEventLoop.__del__ of <_UnixSelectorEventLoop running=False closed=False debug=False>>
Traceback (most recent call last):
  File "/usr/lib/python3.6/asyncio/base_events.py", line 526, in __del__
NameError: name 'ResourceWarning' is not defined
