Exception ignored in: <bound method BaseEventLoop.__del__ of <_UnixSelectorEventLoop running=False closed=False debug=False>>
Traceback (most recent call last):
  File "/usr/lib/python3.6/asyncio/base_events.py", line 526, in __del__
NameError: name 'ResourceWarning' is not defined
Exception ignored in: <bound method BaseEventLoop.__del__ of <_UnixSelectorEventLoop running=False closed=False debug=False>>
Traceback (most recent call last):
  File "/usr/lib/python3.6/asyncio/base_events.py", line 526, in __del__
NameError: name 'ResourceWarning' is not defined
[Wed Dec 23 19:54:08.018924 2020] [wsgi:error] [pid 4956:tid 140362781955840] [remote 68.194.112.101:53147] mod_wsgi (pid=4956): Exception occurred processing WSGI script '/var/www/BrogSite/BrogSite/wsgi.py'.
[Wed Dec 23 19:54:08.026602 2020] [wsgi:error] [pid 4956:tid 140362781955840] [remote 68.194.112.101:53147] Traceback (most recent call last):
[Wed Dec 23 19:54:08.026660 2020] [wsgi:error] [pid 4956:tid 140362781955840] [remote 68.194.112.101:53147]   File "/usr/local/lib/python3.6/dist-packages/django/core/handlers/exception.py", line 47, in inner
[Wed Dec 23 19:54:08.026667 2020] [wsgi:error] [pid 4956:tid 140362781955840] [remote 68.194.112.101:53147]     response = get_response(request)
[Wed Dec 23 19:54:08.026675 2020] [wsgi:error] [pid 4956:tid 140362781955840] [remote 68.194.112.101:53147]   File "/usr/local/lib/python3.6/dist-packages/django/utils/deprecation.py", line 113, in __call__
[Wed Dec 23 19:54:08.026680 2020] [wsgi:error] [pid 4956:tid 140362781955840] [remote 68.194.112.101:53147]     response = self.process_request(request)
[Wed Dec 23 19:54:08.026687 2020] [wsgi:error] [pid 4956:tid 140362781955840] [remote 68.194.112.101:53147]   File "/usr/local/lib/python3.6/dist-packages/django/middleware/common.py", line 48, in process_request
[Wed Dec 23 19:54:08.026692 2020] [wsgi:error] [pid 4956:tid 140362781955840] [remote 68.194.112.101:53147]     host = request.get_host()
[Wed Dec 23 19:54:08.026698 2020] [wsgi:error] [pid 4956:tid 140362781955840] [remote 68.194.112.101:53147]   File "/usr/local/lib/python3.6/dist-packages/django/http/request.py", line 137, in get_host
[Wed Dec 23 19:54:08.026702 2020] [wsgi:error] [pid 4956:tid 140362781955840] [remote 68.194.112.101:53147]     raise DisallowedHost(msg)
[Wed Dec 23 19:54:08.026731 2020] [wsgi:error] [pid 4956:tid 140362781955840] [remote 68.194.112.101:53147] django.core.exceptions.DisallowedHost: Invalid HTTP_HOST header: 'li2192-67.members.linode.com'. You may need to add 'li2192-67.members.linode.com' to ALLOWED_HOSTS.
[Wed Dec 23 19:54:08.026745 2020] [wsgi:error] [pid 4956:tid 140362781955840] [remote 68.194.112.101:53147] 
[Wed Dec 23 19:54:08.026749 2020] [wsgi:error] [pid 4956:tid 140362781955840] [remote 68.194.112.101:53147] During handling of the above exception, another exception occurred:
[Wed Dec 23 19:54:08.026753 2020] [wsgi:error] [pid 4956:tid 140362781955840] [remote 68.194.112.101:53147] 
[Wed Dec 23 19:54:08.026760 2020] [wsgi:error] [pid 4956:tid 140362781955840] [remote 68.194.112.101:53147] Traceback (most recent call last):
[Wed Dec 23 19:54:08.026850 2020] [wsgi:error] [pid 4956:tid 140362781955840] [remote 68.194.112.101:53147]   File "/usr/local/lib/python3.6/dist-packages/django/core/handlers/exception.py", line 120, in get_exception_response
[Wed Dec 23 19:54:08.026856 2020] [wsgi:error] [pid 4956:tid 140362781955840] [remote 68.194.112.101:53147]     callback, param_dict = resolver.resolve_error_handler(status_code)
[Wed Dec 23 19:54:08.026863 2020] [wsgi:error] [pid 4956:tid 140362781955840] [remote 68.194.112.101:53147]   File "/usr/local/lib/python3.6/dist-packages/django/urls/resolvers.py", line 602, in resolve_error_handler
[Wed Dec 23 19:54:08.026867 2020] [wsgi:error] [pid 4956:tid 140362781955840] [remote 68.194.112.101:53147]     callback = getattr(self.urlconf_module, 'handler%s' % view_type, None)
[Wed Dec 23 19:54:08.026874 2020] [wsgi:error] [pid 4956:tid 140362781955840] [remote 68.194.112.101:53147]   File "/usr/local/lib/python3.6/dist-packages/django/utils/functional.py", line 48, in __get__
[Wed Dec 23 19:54:08.026890 2020] [wsgi:error] [pid 4956:tid 140362781955840] [remote 68.194.112.101:53147]     res = instance.__dict__[self.name] = self.func(instance)
[Wed Dec 23 19:54:08.026898 2020] [wsgi:error] [pid 4956:tid 140362781955840] [remote 68.194.112.101:53147]   File "/usr/local/lib/python3.6/dist-packages/django/urls/resolvers.py", line 582, in urlconf_module
[Wed Dec 23 19:54:08.026902 2020] [wsgi:error] [pid 4956:tid 140362781955840] [remote 68.194.112.101:53147]     return import_module(self.urlconf_name)
[Wed Dec 23 19:54:08.026908 2020] [wsgi:error] [pid 4956:tid 140362781955840] [remote 68.194.112.101:53147]   File "/usr/lib/python3.6/importlib/__init__.py", line 126, in import_module
[Wed Dec 23 19:54:08.026912 2020] [wsgi:error] [pid 4956:tid 140362781955840] [remote 68.194.112.101:53147]     return _bootstrap._gcd_import(name[level:], package, level)
[Wed Dec 23 19:54:08.026919 2020] [wsgi:error] [pid 4956:tid 140362781955840] [remote 68.194.112.101:53147]   File "<frozen importlib._bootstrap>", line 994, in _gcd_import
[Wed Dec 23 19:54:08.026925 2020] [wsgi:error] [pid 4956:tid 140362781955840] [remote 68.194.112.101:53147]   File "<frozen importlib._bootstrap>", line 971, in _find_and_load
[Wed Dec 23 19:54:08.026932 2020] [wsgi:error] [pid 4956:tid 140362781955840] [remote 68.194.112.101:53147]   File "<frozen importlib._bootstrap>", line 955, in _find_and_load_unlocked
[Wed Dec 23 19:54:08.026938 2020] [wsgi:error] [pid 4956:tid 140362781955840] [remote 68.194.112.101:53147]   File "<frozen importlib._bootstrap>", line 665, in _load_unlocked
[Wed Dec 23 19:54:08.026945 2020] [wsgi:error] [pid 4956:tid 140362781955840] [remote 68.194.112.101:53147]   File "<frozen importlib._bootstrap_external>", line 678, in exec_module
[Wed Dec 23 19:54:08.026951 2020] [wsgi:error] [pid 4956:tid 140362781955840] [remote 68.194.112.101:53147]   File "<frozen importlib._bootstrap>", line 219, in _call_with_frames_removed
[Wed Dec 23 19:54:08.026958 2020] [wsgi:error] [pid 4956:tid 140362781955840] [remote 68.194.112.101:53147]   File "/var/www/BrogSite/BrogSite/urls.py", line 21, in <module>
[Wed Dec 23 19:54:08.026962 2020] [wsgi:error] [pid 4956:tid 140362781955840] [remote 68.194.112.101:53147]     path("", include("main.urls")),
[Wed Dec 23 19:54:08.026968 2020] [wsgi:error] [pid 4956:tid 140362781955840] [remote 68.194.112.101:53147]   File "/usr/local/lib/python3.6/dist-packages/django/urls/conf.py", line 34, in include
[Wed Dec 23 19:54:08.026972 2020] [wsgi:error] [pid 4956:tid 140362781955840] [remote 68.194.112.101:53147]     urlconf_module = import_module(urlconf_module)
[Wed Dec 23 19:54:08.026978 2020] [wsgi:error] [pid 4956:tid 140362781955840] [remote 68.194.112.101:53147]   File "/usr/lib/python3.6/importlib/__init__.py", line 126, in import_module
[Wed Dec 23 19:54:08.026982 2020] [wsgi:error] [pid 4956:tid 140362781955840] [remote 68.194.112.101:53147]     return _bootstrap._gcd_import(name[level:], package, level)
[Wed Dec 23 19:54:08.026988 2020] [wsgi:error] [pid 4956:tid 140362781955840] [remote 68.194.112.101:53147]   File "<frozen importlib._bootstrap>", line 994, in _gcd_import
[Wed Dec 23 19:54:08.026995 2020] [wsgi:error] [pid 4956:tid 140362781955840] [remote 68.194.112.101:53147]   File "<frozen importlib._bootstrap>", line 971, in _find_and_load
[Wed Dec 23 19:54:08.027001 2020] [wsgi:error] [pid 4956:tid 140362781955840] [remote 68.194.112.101:53147]   File "<frozen importlib._bootstrap>", line 955, in _find_and_load_unlocked
[Wed Dec 23 19:54:08.027008 2020] [wsgi:error] [pid 4956:tid 140362781955840] [remote 68.194.112.101:53147]   File "<frozen importlib._bootstrap>", line 665, in _load_unlocked
[Wed Dec 23 19:54:08.027014 2020] [wsgi:error] [pid 4956:tid 140362781955840] [remote 68.194.112.101:53147]   File "<frozen importlib._bootstrap_external>", line 678, in exec_module
[Wed Dec 23 19:54:08.027021 2020] [wsgi:error] [pid 4956:tid 140362781955840] [remote 68.194.112.101:53147]   File "<frozen importlib._bootstrap>", line 219, in _call_with_frames_removed
[Wed Dec 23 19:54:08.027032 2020] [wsgi:error] [pid 4956:tid 140362781955840] [remote 68.194.112.101:53147]   File "/var/www/BrogSite/main/urls.py", line 3, in <module>
[Wed Dec 23 19:54:08.027036 2020] [wsgi:error] [pid 4956:tid 140362781955840] [remote 68.194.112.101:53147]     from . import views
[Wed Dec 23 19:54:08.027042 2020] [wsgi:error] [pid 4956:tid 140362781955840] [remote 68.194.112.101:53147]   File "/var/www/BrogSite/main/views.py", line 4, in <module>
[Wed Dec 23 19:54:08.027046 2020] [wsgi:error] [pid 4956:tid 140362781955840] [remote 68.194.112.101:53147]     from .scrape import SubredditScraper
[Wed Dec 23 19:54:08.027052 2020] [wsgi:error] [pid 4956:tid 140362781955840] [remote 68.194.112.101:53147]   File "/var/www/BrogSite/main/scrape.py", line 2, in <module>
[Wed Dec 23 19:54:08.027056 2020] [wsgi:error] [pid 4956:tid 140362781955840] [remote 68.194.112.101:53147]     import praw
[Wed Dec 23 19:54:08.027062 2020] [wsgi:error] [pid 4956:tid 140362781955840] [remote 68.194.112.101:53147]   File "/usr/local/lib/python3.6/dist-packages/praw/__init__.py", line 14, in <module>
[Wed Dec 23 19:54:08.027066 2020] [wsgi:error] [pid 4956:tid 140362781955840] [remote 68.194.112.101:53147]     from .reddit import Reddit  # NOQA
[Wed Dec 23 19:54:08.027072 2020] [wsgi:error] [pid 4956:tid 140362781955840] [remote 68.194.112.101:53147]   File "/usr/local/lib/python3.6/dist-packages/praw/reddit.py", line 11, in <module>
[Wed Dec 23 19:54:08.027076 2020] [wsgi:error] [pid 4956:tid 140362781955840] [remote 68.194.112.101:53147]     from prawcore import (
[Wed Dec 23 19:54:08.027082 2020] [wsgi:error] [pid 4956:tid 140362781955840] [remote 68.194.112.101:53147]   File "/usr/local/lib/python3.6/dist-packages/prawcore/__init__.py", line 4, in <module>
[Wed Dec 23 19:54:08.027086 2020] [wsgi:error] [pid 4956:tid 140362781955840] [remote 68.194.112.101:53147]     from .auth import (  # noqa
[Wed Dec 23 19:54:08.027092 2020] [wsgi:error] [pid 4956:tid 140362781955840] [remote 68.194.112.101:53147]   File "/usr/local/lib/python3.6/dist-packages/prawcore/auth.py", line 5, in <module>
[Wed Dec 23 19:54:08.027096 2020] [wsgi:error] [pid 4956:tid 140362781955840] [remote 68.194.112.101:53147]     from requests import Request
[Wed Dec 23 19:54:08.027110 2020] [wsgi:error] [pid 4956:tid 140362781955840] [remote 68.194.112.101:53147] ModuleNotFoundError: No module named 'requests'
[Wed Dec 23 19:54:08.027118 2020] [wsgi:error] [pid 4956:tid 140362781955840] [remote 68.194.112.101:53147] 
[Wed Dec 23 19:54:08.027122 2020] [wsgi:error] [pid 4956:tid 140362781955840] [remote 68.194.112.101:53147] During handling of the above exception, another exception occurred:
[Wed Dec 23 19:54:08.027125 2020] [wsgi:error] [pid 4956:tid 140362781955840] [remote 68.194.112.101:53147] 
[Wed Dec 23 19:54:08.027132 2020] [wsgi:error] [pid 4956:tid 140362781955840] [remote 68.194.112.101:53147] Traceback (most recent call last):
[Wed Dec 23 19:54:08.027232 2020] [wsgi:error] [pid 4956:tid 140362781955840] [remote 68.194.112.101:53147]   File "/usr/local/lib/python3.6/dist-packages/django/core/handlers/exception.py", line 47, in inner
[Wed Dec 23 19:54:08.027237 2020] [wsgi:error] [pid 4956:tid 140362781955840] [remote 68.194.112.101:53147]     response = get_response(request)
[Wed Dec 23 19:54:08.027244 2020] [wsgi:error] [pid 4956:tid 140362781955840] [remote 68.194.112.101:53147]   File "/usr/local/lib/python3.6/dist-packages/django/utils/deprecation.py", line 114, in __call__
[Wed Dec 23 19:54:08.027248 2020] [wsgi:error] [pid 4956:tid 140362781955840] [remote 68.194.112.101:53147]     response = response or self.get_response(request)
[Wed Dec 23 19:54:08.027254 2020] [wsgi:error] [pid 4956:tid 140362781955840] [remote 68.194.112.101:53147]   File "/usr/local/lib/python3.6/dist-packages/django/core/handlers/exception.py", line 49, in inner
[Wed Dec 23 19:54:08.027258 2020] [wsgi:error] [pid 4956:tid 140362781955840] [remote 68.194.112.101:53147]     response = response_for_exception(request, exc)
[Wed Dec 23 19:54:08.027264 2020] [wsgi:error] [pid 4956:tid 140362781955840] [remote 68.194.112.101:53147]   File "/usr/local/lib/python3.6/dist-packages/django/core/handlers/exception.py", line 95, in response_for_exception
[Wed Dec 23 19:54:08.027272 2020] [wsgi:error] [pid 4956:tid 140362781955840] [remote 68.194.112.101:53147]     response = get_exception_response(request, get_resolver(get_urlconf()), 400, exc)
[Wed Dec 23 19:54:08.027279 2020] [wsgi:error] [pid 4956:tid 140362781955840] [remote 68.194.112.101:53147]   File "/usr/local/lib/python3.6/dist-packages/django/core/handlers/exception.py", line 124, in get_exception_response
[Wed Dec 23 19:54:08.027283 2020] [wsgi:error] [pid 4956:tid 140362781955840] [remote 68.194.112.101:53147]     response = handle_uncaught_exception(request, resolver, sys.exc_info())
[Wed Dec 23 19:54:08.027290 2020] [wsgi:error] [pid 4956:tid 140362781955840] [remote 68.194.112.101:53147]   File "/usr/local/lib/python3.6/dist-packages/django/core/handlers/exception.py", line 141, in handle_uncaught_exception
[Wed Dec 23 19:54:08.027294 2020] [wsgi:error] [pid 4956:tid 140362781955840] [remote 68.194.112.101:53147]     callback, param_dict = resolver.resolve_error_handler(500)
[Wed Dec 23 19:54:08.027300 2020] [wsgi:error] [pid 4956:tid 140362781955840] [remote 68.194.112.101:53147]   File "/usr/local/lib/python3.6/dist-packages/django/urls/resolvers.py", line 602, in resolve_error_handler
[Wed Dec 23 19:54:08.027304 2020] [wsgi:error] [pid 4956:tid 140362781955840] [remote 68.194.112.101:53147]     callback = getattr(self.urlconf_module, 'handler%s' % view_type, None)
[Wed Dec 23 19:54:08.027310 2020] [wsgi:error] [pid 4956:tid 140362781955840] [remote 68.194.112.101:53147]   File "/usr/local/lib/python3.6/dist-packages/django/utils/functional.py", line 48, in __get__
[Wed Dec 23 19:54:08.027314 2020] [wsgi:error] [pid 4956:tid 140362781955840] [remote 68.194.112.101:53147]     res = instance.__dict__[self.name] = self.func(instance)
[Wed Dec 23 19:54:08.027321 2020] [wsgi:error] [pid 4956:tid 140362781955840] [remote 68.194.112.101:53147]   File "/usr/local/lib/python3.6/dist-packages/django/urls/resolvers.py", line 582, in urlconf_module
[Wed Dec 23 19:54:08.027325 2020] [wsgi:error] [pid 4956:tid 140362781955840] [remote 68.194.112.101:53147]     return import_module(self.urlconf_name)
[Wed Dec 23 19:54:08.027331 2020] [wsgi:error] [pid 4956:tid 140362781955840] [remote 68.194.112.101:53147]   File "/usr/lib/python3.6/importlib/__init__.py", line 126, in import_module
[Wed Dec 23 19:54:08.027335 2020] [wsgi:error] [pid 4956:tid 140362781955840] [remote 68.194.112.101:53147]     return _bootstrap._gcd_import(name[level:], package, level)
[Wed Dec 23 19:54:08.027341 2020] [wsgi:error] [pid 4956:tid 140362781955840] [remote 68.194.112.101:53147]   File "<frozen importlib._bootstrap>", line 994, in _gcd_import
[Wed Dec 23 19:54:08.027347 2020] [wsgi:error] [pid 4956:tid 140362781955840] [remote 68.194.112.101:53147]   File "<frozen importlib._bootstrap>", line 971, in _find_and_load
[Wed Dec 23 19:54:08.027354 2020] [wsgi:error] [pid 4956:tid 140362781955840] [remote 68.194.112.101:53147]   File "<frozen importlib._bootstrap>", line 955, in _find_and_load_unlocked
[Wed Dec 23 19:54:08.027360 2020] [wsgi:error] [pid 4956:tid 140362781955840] [remote 68.194.112.101:53147]   File "<frozen importlib._bootstrap>", line 665, in _load_unlocked
[Wed Dec 23 19:54:08.027367 2020] [wsgi:error] [pid 4956:tid 140362781955840] [remote 68.194.112.101:53147]   File "<frozen importlib._bootstrap_external>", line 678, in exec_module
[Wed Dec 23 19:54:08.027373 2020] [wsgi:error] [pid 4956:tid 140362781955840] [remote 68.194.112.101:53147]   File "<frozen importlib._bootstrap>", line 219, in _call_with_frames_removed
[Wed Dec 23 19:54:08.027380 2020] [wsgi:error] [pid 4956:tid 140362781955840] [remote 68.194.112.101:53147]   File "/var/www/BrogSite/BrogSite/urls.py", line 21, in <module>
[Wed Dec 23 19:54:08.027383 2020] [wsgi:error] [pid 4956:tid 140362781955840] [remote 68.194.112.101:53147]     path("", include("main.urls")),
[Wed Dec 23 19:54:08.027393 2020] [wsgi:error] [pid 4956:tid 140362781955840] [remote 68.194.112.101:53147]   File "/usr/local/lib/python3.6/dist-packages/django/urls/conf.py", line 34, in include
[Wed Dec 23 19:54:08.027397 2020] [wsgi:error] [pid 4956:tid 140362781955840] [remote 68.194.112.101:53147]     urlconf_module = import_module(urlconf_module)
[Wed Dec 23 19:54:08.027403 2020] [wsgi:error] [pid 4956:tid 140362781955840] [remote 68.194.112.101:53147]   File "/usr/lib/python3.6/importlib/__init__.py", line 126, in import_module
[Wed Dec 23 19:54:08.027407 2020] [wsgi:error] [pid 4956:tid 140362781955840] [remote 68.194.112.101:53147]     return _bootstrap._gcd_import(name[level:], package, level)
[Wed Dec 23 19:54:08.027413 2020] [wsgi:error] [pid 4956:tid 140362781955840] [remote 68.194.112.101:53147]   File "<frozen importlib._bootstrap>", line 994, in _gcd_import
[Wed Dec 23 19:54:08.027420 2020] [wsgi:error] [pid 4956:tid 140362781955840] [remote 68.194.112.101:53147]   File "<frozen importlib._bootstrap>", line 971, in _find_and_load
[Wed Dec 23 19:54:08.027426 2020] [wsgi:error] [pid 4956:tid 140362781955840] [remote 68.194.112.101:53147]   File "<frozen importlib._bootstrap>", line 955, in _find_and_load_unlocked
[Wed Dec 23 19:54:08.027432 2020] [wsgi:error] [pid 4956:tid 140362781955840] [remote 68.194.112.101:53147]   File "<frozen importlib._bootstrap>", line 665, in _load_unlocked
[Wed Dec 23 19:54:08.027439 2020] [wsgi:error] [pid 4956:tid 140362781955840] [remote 68.194.112.101:53147]   File "<frozen importlib._bootstrap_external>", line 678, in exec_module
[Wed Dec 23 19:54:08.027445 2020] [wsgi:error] [pid 4956:tid 140362781955840] [remote 68.194.112.101:53147]   File "<frozen importlib._bootstrap>", line 219, in _call_with_frames_removed
[Wed Dec 23 19:54:08.027452 2020] [wsgi:error] [pid 4956:tid 140362781955840] [remote 68.194.112.101:53147]   File "/var/www/BrogSite/main/urls.py", line 3, in <module>
[Wed Dec 23 19:54:08.027455 2020] [wsgi:error] [pid 4956:tid 140362781955840] [remote 68.194.112.101:53147]     from . import views
[Wed Dec 23 19:54:08.027461 2020] [wsgi:error] [pid 4956:tid 140362781955840] [remote 68.194.112.101:53147]   File "/var/www/BrogSite/main/views.py", line 4, in <module>
[Wed Dec 23 19:54:08.027465 2020] [wsgi:error] [pid 4956:tid 140362781955840] [remote 68.194.112.101:53147]     from .scrape import SubredditScraper
[Wed Dec 23 19:54:08.027471 2020] [wsgi:error] [pid 4956:tid 140362781955840] [remote 68.194.112.101:53147]   File "/var/www/BrogSite/main/scrape.py", line 2, in <module>
[Wed Dec 23 19:54:08.027475 2020] [wsgi:error] [pid 4956:tid 140362781955840] [remote 68.194.112.101:53147]     import praw
[Wed Dec 23 19:54:08.027481 2020] [wsgi:error] [pid 4956:tid 140362781955840] [remote 68.194.112.101:53147]   File "/usr/local/lib/python3.6/dist-packages/praw/__init__.py", line 14, in <module>
[Wed Dec 23 19:54:08.027485 2020] [wsgi:error] [pid 4956:tid 140362781955840] [remote 68.194.112.101:53147]     from .reddit import Reddit  # NOQA
[Wed Dec 23 19:54:08.027491 2020] [wsgi:error] [pid 4956:tid 140362781955840] [remote 68.194.112.101:53147]   File "/usr/local/lib/python3.6/dist-packages/praw/reddit.py", line 11, in <module>
[Wed Dec 23 19:54:08.027495 2020] [wsgi:error] [pid 4956:tid 140362781955840] [remote 68.194.112.101:53147]     from prawcore import (
[Wed Dec 23 19:54:08.027501 2020] [wsgi:error] [pid 4956:tid 140362781955840] [remote 68.194.112.101:53147]   File "/usr/local/lib/python3.6/dist-packages/prawcore/__init__.py", line 4, in <module>
[Wed Dec 23 19:54:08.027505 2020] [wsgi:error] [pid 4956:tid 140362781955840] [remote 68.194.112.101:53147]     from .auth import (  # noqa
[Wed Dec 23 19:54:08.027511 2020] [wsgi:error] [pid 4956:tid 140362781955840] [remote 68.194.112.101:53147]   File "/usr/local/lib/python3.6/dist-packages/prawcore/auth.py", line 5, in <module>
[Wed Dec 23 19:54:08.027515 2020] [wsgi:error] [pid 4956:tid 140362781955840] [remote 68.194.112.101:53147]     from requests import Request
[Wed Dec 23 19:54:08.027560 2020] [wsgi:error] [pid 4956:tid 140362781955840] [remote 68.194.112.101:53147] ModuleNotFoundError: No module named 'requests'
[Wed Dec 23 19:54:08.027574 2020] [wsgi:error] [pid 4956:tid 140362781955840] [remote 68.194.112.101:53147] 
[Wed Dec 23 19:54:08.027578 2020] [wsgi:error] [pid 4956:tid 140362781955840] [remote 68.194.112.101:53147] During handling of the above exception, another exception occurred:
[Wed Dec 23 19:54:08.027582 2020] [wsgi:error] [pid 4956:tid 140362781955840] [remote 68.194.112.101:53147] 
[Wed Dec 23 19:54:08.027588 2020] [wsgi:error] [pid 4956:tid 140362781955840] [remote 68.194.112.101:53147] Traceback (most recent call last):
[Wed Dec 23 19:54:08.027685 2020] [wsgi:error] [pid 4956:tid 140362781955840] [remote 68.194.112.101:53147]   File "/usr/local/lib/python3.6/dist-packages/django/core/handlers/exception.py", line 47, in inner
[Wed Dec 23 19:54:08.027690 2020] [wsgi:error] [pid 4956:tid 140362781955840] [remote 68.194.112.101:53147]     response = get_response(request)
[Wed Dec 23 19:54:08.027696 2020] [wsgi:error] [pid 4956:tid 140362781955840] [remote 68.194.112.101:53147]   File "/usr/local/lib/python3.6/dist-packages/django/utils/deprecation.py", line 114, in __call__
[Wed Dec 23 19:54:08.027700 2020] [wsgi:error] [pid 4956:tid 140362781955840] [remote 68.194.112.101:53147]     response = response or self.get_response(request)
[Wed Dec 23 19:54:08.027706 2020] [wsgi:error] [pid 4956:tid 140362781955840] [remote 68.194.112.101:53147]   File "/usr/local/lib/python3.6/dist-packages/django/core/handlers/exception.py", line 49, in inner
[Wed Dec 23 19:54:08.027710 2020] [wsgi:error] [pid 4956:tid 140362781955840] [remote 68.194.112.101:53147]     response = response_for_exception(request, exc)
[Wed Dec 23 19:54:08.027716 2020] [wsgi:error] [pid 4956:tid 140362781955840] [remote 68.194.112.101:53147]   File "/usr/local/lib/python3.6/dist-packages/django/core/handlers/exception.py", line 103, in response_for_exception
[Wed Dec 23 19:54:08.027720 2020] [wsgi:error] [pid 4956:tid 140362781955840] [remote 68.194.112.101:53147]     response = handle_uncaught_exception(request, get_resolver(get_urlconf()), sys.exc_info())
[Wed Dec 23 19:54:08.027727 2020] [wsgi:error] [pid 4956:tid 140362781955840] [remote 68.194.112.101:53147]   File "/usr/local/lib/python3.6/dist-packages/django/core/handlers/exception.py", line 141, in handle_uncaught_exception
[Wed Dec 23 19:54:08.027730 2020] [wsgi:error] [pid 4956:tid 140362781955840] [remote 68.194.112.101:53147]     callback, param_dict = resolver.resolve_error_handler(500)
[Wed Dec 23 19:54:08.027736 2020] [wsgi:error] [pid 4956:tid 140362781955840] [remote 68.194.112.101:53147]   File "/usr/local/lib/python3.6/dist-packages/django/urls/resolvers.py", line 602, in resolve_error_handler
[Wed Dec 23 19:54:08.027741 2020] [wsgi:error] [pid 4956:tid 140362781955840] [remote 68.194.112.101:53147]     callback = getattr(self.urlconf_module, 'handler%s' % view_type, None)
[Wed Dec 23 19:54:08.027747 2020] [wsgi:error] [pid 4956:tid 140362781955840] [remote 68.194.112.101:53147]   File "/usr/local/lib/python3.6/dist-packages/django/utils/functional.py", line 48, in __get__
[Wed Dec 23 19:54:08.027751 2020] [wsgi:error] [pid 4956:tid 140362781955840] [remote 68.194.112.101:53147]     res = instance.__dict__[self.name] = self.func(instance)
[Wed Dec 23 19:54:08.027757 2020] [wsgi:error] [pid 4956:tid 140362781955840] [remote 68.194.112.101:53147]   File "/usr/local/lib/python3.6/dist-packages/django/urls/resolvers.py", line 582, in urlconf_module
[Wed Dec 23 19:54:08.027761 2020] [wsgi:error] [pid 4956:tid 140362781955840] [remote 68.194.112.101:53147]     return import_module(self.urlconf_name)
[Wed Dec 23 19:54:08.027767 2020] [wsgi:error] [pid 4956:tid 140362781955840] [remote 68.194.112.101:53147]   File "/usr/lib/python3.6/importlib/__init__.py", line 126, in import_module
[Wed Dec 23 19:54:08.027771 2020] [wsgi:error] [pid 4956:tid 140362781955840] [remote 68.194.112.101:53147]     return _bootstrap._gcd_import(name[level:], package, level)
[Wed Dec 23 19:54:08.027777 2020] [wsgi:error] [pid 4956:tid 140362781955840] [remote 68.194.112.101:53147]   File "<frozen importlib._bootstrap>", line 994, in _gcd_import
[Wed Dec 23 19:54:08.027787 2020] [wsgi:error] [pid 4956:tid 140362781955840] [remote 68.194.112.101:53147]   File "<frozen importlib._bootstrap>", line 971, in _find_and_load
[Wed Dec 23 19:54:08.027794 2020] [wsgi:error] [pid 4956:tid 140362781955840] [remote 68.194.112.101:53147]   File "<frozen importlib._bootstrap>", line 955, in _find_and_load_unlocked
[Wed Dec 23 19:54:08.027801 2020] [wsgi:error] [pid 4956:tid 140362781955840] [remote 68.194.112.101:53147]   File "<frozen importlib._bootstrap>", line 665, in _load_unlocked
[Wed Dec 23 19:54:08.027807 2020] [wsgi:error] [pid 4956:tid 140362781955840] [remote 68.194.112.101:53147]   File "<frozen importlib._bootstrap_external>", line 678, in exec_module
[Wed Dec 23 19:54:08.027813 2020] [wsgi:error] [pid 4956:tid 140362781955840] [remote 68.194.112.101:53147]   File "<frozen importlib._bootstrap>", line 219, in _call_with_frames_removed
[Wed Dec 23 19:54:08.027820 2020] [wsgi:error] [pid 4956:tid 140362781955840] [remote 68.194.112.101:53147]   File "/var/www/BrogSite/BrogSite/urls.py", line 21, in <module>
[Wed Dec 23 19:54:08.027824 2020] [wsgi:error] [pid 4956:tid 140362781955840] [remote 68.194.112.101:53147]     path("", include("main.urls")),
[Wed Dec 23 19:54:08.027830 2020] [wsgi:error] [pid 4956:tid 140362781955840] [remote 68.194.112.101:53147]   File "/usr/local/lib/python3.6/dist-packages/django/urls/conf.py", line 34, in include
[Wed Dec 23 19:54:08.027833 2020] [wsgi:error] [pid 4956:tid 140362781955840] [remote 68.194.112.101:53147]     urlconf_module = import_module(urlconf_module)
[Wed Dec 23 19:54:08.027839 2020] [wsgi:error] [pid 4956:tid 140362781955840] [remote 68.194.112.101:53147]   File "/usr/lib/python3.6/importlib/__init__.py", line 126, in import_module
[Wed Dec 23 19:54:08.027843 2020] [wsgi:error] [pid 4956:tid 140362781955840] [remote 68.194.112.101:53147]     return _bootstrap._gcd_import(name[level:], package, level)
[Wed Dec 23 19:54:08.027849 2020] [wsgi:error] [pid 4956:tid 140362781955840] [remote 68.194.112.101:53147]   File "<frozen importlib._bootstrap>", line 994, in _gcd_import
[Wed Dec 23 19:54:08.027856 2020] [wsgi:error] [pid 4956:tid 140362781955840] [remote 68.194.112.101:53147]   File "<frozen importlib._bootstrap>", line 971, in _find_and_load
[Wed Dec 23 19:54:08.027862 2020] [wsgi:error] [pid 4956:tid 140362781955840] [remote 68.194.112.101:53147]   File "<frozen importlib._bootstrap>", line 955, in _find_and_load_unlocked
[Wed Dec 23 19:54:08.027868 2020] [wsgi:error] [pid 4956:tid 140362781955840] [remote 68.194.112.101:53147]   File "<frozen importlib._bootstrap>", line 665, in _load_unlocked
[Wed Dec 23 19:54:08.027875 2020] [wsgi:error] [pid 4956:tid 140362781955840] [remote 68.194.112.101:53147]   File "<frozen importlib._bootstrap_external>", line 678, in exec_module
[Wed Dec 23 19:54:08.027881 2020] [wsgi:error] [pid 4956:tid 140362781955840] [remote 68.194.112.101:53147]   File "<frozen importlib._bootstrap>", line 219, in _call_with_frames_removed
[Wed Dec 23 19:54:08.027887 2020] [wsgi:error] [pid 4956:tid 140362781955840] [remote 68.194.112.101:53147]   File "/var/www/BrogSite/main/urls.py", line 3, in <module>
[Wed Dec 23 19:54:08.027891 2020] [wsgi:error] [pid 4956:tid 140362781955840] [remote 68.194.112.101:53147]     from . import views
[Wed Dec 23 19:54:08.027897 2020] [wsgi:error] [pid 4956:tid 140362781955840] [remote 68.194.112.101:53147]   File "/var/www/BrogSite/main/views.py", line 4, in <module>
[Wed Dec 23 19:54:08.027901 2020] [wsgi:error] [pid 4956:tid 140362781955840] [remote 68.194.112.101:53147]     from .scrape import SubredditScraper
[Wed Dec 23 19:54:08.027907 2020] [wsgi:error] [pid 4956:tid 140362781955840] [remote 68.194.112.101:53147]   File "/var/www/BrogSite/main/scrape.py", line 2, in <module>
[Wed Dec 23 19:54:08.027910 2020] [wsgi:error] [pid 4956:tid 140362781955840] [remote 68.194.112.101:53147]     import praw
[Wed Dec 23 19:54:08.027916 2020] [wsgi:error] [pid 4956:tid 140362781955840] [remote 68.194.112.101:53147]   File "/usr/local/lib/python3.6/dist-packages/praw/__init__.py", line 14, in <module>
[Wed Dec 23 19:54:08.027923 2020] [wsgi:error] [pid 4956:tid 140362781955840] [remote 68.194.112.101:53147]     from .reddit import Reddit  # NOQA
[Wed Dec 23 19:54:08.027930 2020] [wsgi:error] [pid 4956:tid 140362781955840] [remote 68.194.112.101:53147]   File "/usr/local/lib/python3.6/dist-packages/praw/reddit.py", line 11, in <module>
[Wed Dec 23 19:54:08.027933 2020] [wsgi:error] [pid 4956:tid 140362781955840] [remote 68.194.112.101:53147]     from prawcore import (
[Wed Dec 23 19:54:08.027939 2020] [wsgi:error] [pid 4956:tid 140362781955840] [remote 68.194.112.101:53147]   File "/usr/local/lib/python3.6/dist-packages/prawcore/__init__.py", line 4, in <module>
[Wed Dec 23 19:54:08.027943 2020] [wsgi:error] [pid 4956:tid 140362781955840] [remote 68.194.112.101:53147]     from .auth import (  # noqa
[Wed Dec 23 19:54:08.027949 2020] [wsgi:error] [pid 4956:tid 140362781955840] [remote 68.194.112.101:53147]   File "/usr/local/lib/python3.6/dist-packages/prawcore/auth.py", line 5, in <module>
[Wed Dec 23 19:54:08.027953 2020] [wsgi:error] [pid 4956:tid 140362781955840] [remote 68.194.112.101:53147]     from requests import Request
[Wed Dec 23 19:54:08.027964 2020] [wsgi:error] [pid 4956:tid 140362781955840] [remote 68.194.112.101:53147] ModuleNotFoundError: No module named 'requests'
[Wed Dec 23 19:54:08.027972 2020] [wsgi:error] [pid 4956:tid 140362781955840] [remote 68.194.112.101:53147] 
[Wed Dec 23 19:54:08.027975 2020] [wsgi:error] [pid 4956:tid 140362781955840] [remote 68.194.112.101:53147] During handling of the above exception, another exception occurred:
[Wed Dec 23 19:54:08.027979 2020] [wsgi:error] [pid 4956:tid 140362781955840] [remote 68.194.112.101:53147] 
[Wed Dec 23 19:54:08.027985 2020] [wsgi:error] [pid 4956:tid 140362781955840] [remote 68.194.112.101:53147] Traceback (most recent call last):
[Wed Dec 23 19:54:08.028080 2020] [wsgi:error] [pid 4956:tid 140362781955840] [remote 68.194.112.101:53147]   File "/usr/local/lib/python3.6/dist-packages/django/core/handlers/wsgi.py", line 133, in __call__
[Wed Dec 23 19:54:08.028085 2020] [wsgi:error] [pid 4956:tid 140362781955840] [remote 68.194.112.101:53147]     response = self.get_response(request)
[Wed Dec 23 19:54:08.028091 2020] [wsgi:error] [pid 4956:tid 140362781955840] [remote 68.194.112.101:53147]   File "/usr/local/lib/python3.6/dist-packages/django/core/handlers/base.py", line 128, in get_response
[Wed Dec 23 19:54:08.028095 2020] [wsgi:error] [pid 4956:tid 140362781955840] [remote 68.194.112.101:53147]     response = self._middleware_chain(request)
[Wed Dec 23 19:54:08.028101 2020] [wsgi:error] [pid 4956:tid 140362781955840] [remote 68.194.112.101:53147]   File "/usr/local/lib/python3.6/dist-packages/django/core/handlers/exception.py", line 49, in inner
[Wed Dec 23 19:54:08.028105 2020] [wsgi:error] [pid 4956:tid 140362781955840] [remote 68.194.112.101:53147]     response = response_for_exception(request, exc)
[Wed Dec 23 19:54:08.028111 2020] [wsgi:error] [pid 4956:tid 140362781955840] [remote 68.194.112.101:53147]   File "/usr/local/lib/python3.6/dist-packages/django/core/handlers/exception.py", line 103, in response_for_exception
[Wed Dec 23 19:54:08.028115 2020] [wsgi:error] [pid 4956:tid 140362781955840] [remote 68.194.112.101:53147]     response = handle_uncaught_exception(request, get_resolver(get_urlconf()), sys.exc_info())
[Wed Dec 23 19:54:08.028121 2020] [wsgi:error] [pid 4956:tid 140362781955840] [remote 68.194.112.101:53147]   File "/usr/local/lib/python3.6/dist-packages/django/core/handlers/exception.py", line 141, in handle_uncaught_exception
[Wed Dec 23 19:54:08.028125 2020] [wsgi:error] [pid 4956:tid 140362781955840] [remote 68.194.112.101:53147]     callback, param_dict = resolver.resolve_error_handler(500)
[Wed Dec 23 19:54:08.028131 2020] [wsgi:error] [pid 4956:tid 140362781955840] [remote 68.194.112.101:53147]   File "/usr/local/lib/python3.6/dist-packages/django/urls/resolvers.py", line 602, in resolve_error_handler
[Wed Dec 23 19:54:08.028139 2020] [wsgi:error] [pid 4956:tid 140362781955840] [remote 68.194.112.101:53147]     callback = getattr(self.urlconf_module, 'handler%s' % view_type, None)
[Wed Dec 23 19:54:08.028146 2020] [wsgi:error] [pid 4956:tid 140362781955840] [remote 68.194.112.101:53147]   File "/usr/local/lib/python3.6/dist-packages/django/utils/functional.py", line 48, in __get__
[Wed Dec 23 19:54:08.028150 2020] [wsgi:error] [pid 4956:tid 140362781955840] [remote 68.194.112.101:53147]     res = instance.__dict__[self.name] = self.func(instance)
[Wed Dec 23 19:54:08.028156 2020] [wsgi:error] [pid 4956:tid 140362781955840] [remote 68.194.112.101:53147]   File "/usr/local/lib/python3.6/dist-packages/django/urls/resolvers.py", line 582, in urlconf_module
[Wed Dec 23 19:54:08.028160 2020] [wsgi:error] [pid 4956:tid 140362781955840] [remote 68.194.112.101:53147]     return import_module(self.urlconf_name)
[Wed Dec 23 19:54:08.028166 2020] [wsgi:error] [pid 4956:tid 140362781955840] [remote 68.194.112.101:53147]   File "/usr/lib/python3.6/importlib/__init__.py", line 126, in import_module
[Wed Dec 23 19:54:08.028169 2020] [wsgi:error] [pid 4956:tid 140362781955840] [remote 68.194.112.101:53147]     return _bootstrap._gcd_import(name[level:], package, level)
[Wed Dec 23 19:54:08.028175 2020] [wsgi:error] [pid 4956:tid 140362781955840] [remote 68.194.112.101:53147]   File "<frozen importlib._bootstrap>", line 994, in _gcd_import
[Wed Dec 23 19:54:08.028182 2020] [wsgi:error] [pid 4956:tid 140362781955840] [remote 68.194.112.101:53147]   File "<frozen importlib._bootstrap>", line 971, in _find_and_load
[Wed Dec 23 19:54:08.028188 2020] [wsgi:error] [pid 4956:tid 140362781955840] [remote 68.194.112.101:53147]   File "<frozen importlib._bootstrap>", line 955, in _find_and_load_unlocked
[Wed Dec 23 19:54:08.028194 2020] [wsgi:error] [pid 4956:tid 140362781955840] [remote 68.194.112.101:53147]   File "<frozen importlib._bootstrap>", line 665, in _load_unlocked
[Wed Dec 23 19:54:08.028200 2020] [wsgi:error] [pid 4956:tid 140362781955840] [remote 68.194.112.101:53147]   File "<frozen importlib._bootstrap_external>", line 678, in exec_module
[Wed Dec 23 19:54:08.028207 2020] [wsgi:error] [pid 4956:tid 140362781955840] [remote 68.194.112.101:53147]   File "<frozen importlib._bootstrap>", line 219, in _call_with_frames_removed
[Wed Dec 23 19:54:08.028213 2020] [wsgi:error] [pid 4956:tid 140362781955840] [remote 68.194.112.101:53147]   File "/var/www/BrogSite/BrogSite/urls.py", line 21, in <module>
[Wed Dec 23 19:54:08.028217 2020] [wsgi:error] [pid 4956:tid 140362781955840] [remote 68.194.112.101:53147]     path("", include("main.urls")),
[Wed Dec 23 19:54:08.028223 2020] [wsgi:error] [pid 4956:tid 140362781955840] [remote 68.194.112.101:53147]   File "/usr/local/lib/python3.6/dist-packages/django/urls/conf.py", line 34, in include
[Wed Dec 23 19:54:08.028227 2020] [wsgi:error] [pid 4956:tid 140362781955840] [remote 68.194.112.101:53147]     urlconf_module = import_module(urlconf_module)
[Wed Dec 23 19:54:08.028233 2020] [wsgi:error] [pid 4956:tid 140362781955840] [remote 68.194.112.101:53147]   File "/usr/lib/python3.6/importlib/__init__.py", line 126, in import_module
[Wed Dec 23 19:54:08.028237 2020] [wsgi:error] [pid 4956:tid 140362781955840] [remote 68.194.112.101:53147]     return _bootstrap._gcd_import(name[level:], package, level)
[Wed Dec 23 19:54:08.028243 2020] [wsgi:error] [pid 4956:tid 140362781955840] [remote 68.194.112.101:53147]   File "<frozen importlib._bootstrap>", line 994, in _gcd_import
[Wed Dec 23 19:54:08.028249 2020] [wsgi:error] [pid 4956:tid 140362781955840] [remote 68.194.112.101:53147]   File "<frozen importlib._bootstrap>", line 971, in _find_and_load
[Wed Dec 23 19:54:08.028255 2020] [wsgi:error] [pid 4956:tid 140362781955840] [remote 68.194.112.101:53147]   File "<frozen importlib._bootstrap>", line 955, in _find_and_load_unlocked
[Wed Dec 23 19:54:08.028261 2020] [wsgi:error] [pid 4956:tid 140362781955840] [remote 68.194.112.101:53147]   File "<frozen importlib._bootstrap>", line 665, in _load_unlocked
[Wed Dec 23 19:54:08.028271 2020] [wsgi:error] [pid 4956:tid 140362781955840] [remote 68.194.112.101:53147]   File "<frozen importlib._bootstrap_external>", line 678, in exec_module
[Wed Dec 23 19:54:08.028278 2020] [wsgi:error] [pid 4956:tid 140362781955840] [remote 68.194.112.101:53147]   File "<frozen importlib._bootstrap>", line 219, in _call_with_frames_removed
[Wed Dec 23 19:54:08.028284 2020] [wsgi:error] [pid 4956:tid 140362781955840] [remote 68.194.112.101:53147]   File "/var/www/BrogSite/main/urls.py", line 3, in <module>
[Wed Dec 23 19:54:08.028288 2020] [wsgi:error] [pid 4956:tid 140362781955840] [remote 68.194.112.101:53147]     from . import views
[Wed Dec 23 19:54:08.028294 2020] [wsgi:error] [pid 4956:tid 140362781955840] [remote 68.194.112.101:53147]   File "/var/www/BrogSite/main/views.py", line 4, in <module>
[Wed Dec 23 19:54:08.028297 2020] [wsgi:error] [pid 4956:tid 140362781955840] [remote 68.194.112.101:53147]     from .scrape import SubredditScraper
[Wed Dec 23 19:54:08.028303 2020] [wsgi:error] [pid 4956:tid 140362781955840] [remote 68.194.112.101:53147]   File "/var/www/BrogSite/main/scrape.py", line 2, in <module>
[Wed Dec 23 19:54:08.028307 2020] [wsgi:error] [pid 4956:tid 140362781955840] [remote 68.194.112.101:53147]     import praw
[Wed Dec 23 19:54:08.028313 2020] [wsgi:error] [pid 4956:tid 140362781955840] [remote 68.194.112.101:53147]   File "/usr/local/lib/python3.6/dist-packages/praw/__init__.py", line 14, in <module>
[Wed Dec 23 19:54:08.028317 2020] [wsgi:error] [pid 4956:tid 140362781955840] [remote 68.194.112.101:53147]     from .reddit import Reddit  # NOQA
[Wed Dec 23 19:54:08.028323 2020] [wsgi:error] [pid 4956:tid 140362781955840] [remote 68.194.112.101:53147]   File "/usr/local/lib/python3.6/dist-packages/praw/reddit.py", line 11, in <module>
[Wed Dec 23 19:54:08.028326 2020] [wsgi:error] [pid 4956:tid 140362781955840] [remote 68.194.112.101:53147]     from prawcore import (
[Wed Dec 23 19:54:08.028332 2020] [wsgi:error] [pid 4956:tid 140362781955840] [remote 68.194.112.101:53147]   File "/usr/local/lib/python3.6/dist-packages/prawcore/__init__.py", line 4, in <module>
[Wed Dec 23 19:54:08.028336 2020] [wsgi:error] [pid 4956:tid 140362781955840] [remote 68.194.112.101:53147]     from .auth import (  # noqa
[Wed Dec 23 19:54:08.028342 2020] [wsgi:error] [pid 4956:tid 140362781955840] [remote 68.194.112.101:53147]   File "/usr/local/lib/python3.6/dist-packages/prawcore/auth.py", line 5, in <module>
[Wed Dec 23 19:54:08.028346 2020] [wsgi:error] [pid 4956:tid 140362781955840] [remote 68.194.112.101:53147]     from requests import Request
[Wed Dec 23 19:54:08.028356 2020] [wsgi:error] [pid 4956:tid 140362781955840] [remote 68.194.112.101:53147] ModuleNotFoundError: No module named 'requests'
